Workbook

Sheet Client ID Records_v1
A1: Date Received | B1: Client Name | C1: Assigned Sex At Birth | D1: Client ID Number | F1: Status | G1: Designation | H1: Institution | I1: Department / Laboratory | J1: Telephone Number | K1: Mobile Number | L1: Fax Number | M1: Email Address | N1: Mailing Address
A2: 2019
A3: 43873 | B3: Philippine Genome Center Visayas | D3: CL-2019- | E3: 000 | F3: Ongoing
A4: 2020
A5: 43873 | B5: Nowena S. Solidum | C5: F | D5: CL-2020- | E5: 1 | F5: Completed | G5: Instructor | H5: Capiz State University | I5: Fishery Department | J5: N/A | K5: 9983950535 | L5: N/A | M5: nowena_solidum@yahoo.com | N5: Fishery Department, Capiz State University - Dayao Satellite College, Dayao, Roxas City, Capiz
A6: 43873 | B6: Marissa C. Naorbe | C6: F | D6: CL-2020- | E6: 2 | F6: Completed | G6: Instructor | H6: Capiz State University | I6: Fishery Department | J6: N/A | K6: 9506798777 | L6: N/A | M6: castromarissa99@gmail.com | N6: Fishery Department, Capiz State University - Dayao Satellite College, Dayao, Roxas City, Capiz
A7: 43873 | B7: Shirleen Grace Brillantes | C7: F | D7: CL-2020- | E7: 3 | F7: Completed | G7: Faculty | H7: Samar State University | I7: Marine Biology | J7: N/A | K7: 9177145364 | L7: N/A | M7: sweetbrillantes@gmail.com | N7: Samar State University - Mercedes, Mercedes, Catbalogan City, Samar 6700
A8: 43873 | B8: Irene Jean C. Lagumbay | C8: F | D8: CL-2020- | E8: 4 | F8: Completed | G8: Instructor I | H8: Samar State University | I8: Marine Biology | J8: N/A | K8: 9165866013 | L8: N/A | M8: irenelagumbay95@gmail.com | N8: Talisay, Bontoc, Southern Leyte
A9: 43873 | B9: Rhodmar D. Panis | C9: M | D9: CL-2020- | E9: 5 | F9: Completed | G9: SRS I | H9: Samar State University | I9: OVPRES/ Micro Lab | J9: N/A | K9: 9056728581 | L9: N/A | M9: rhodmar.divino@ssu.up.edu.ph | N9: N/A
A10: 43873 | B10: Jay T. Torrefiel | C10: M | D10: CL-2020- | E10: 6 | F10: Completed | G10: Instructor | H10: UPV Tacloban College | I10: DNSM | J10: N/A | K10: 9058848900 | L10: N/A | M10: jattorrefiel@gmail.com | N10: 779 San Mateo St., Brangay 4, Jaro, Leyte
A11: 43873 | B11: Rhyzz Jane Balinos | C11: F | D11: CL-2020- | E11: 7 | F11: Completed | G11: Laboratory Aide | H11: UP Visayas | I11: CFOS IA (DOST TGMPPEFET) | J11: N/A | K11: 9666553130 | L11: N/A | M11: rhyzz.jane@gmail.com | N11: Bolho, Miagao, Iloilo
A12: 43873 | B12: Mary Antonette F. Atilano | C12: F | D12: CL-2020- | E12: 8 | F12: Completed | G12: University Research Associate I | H12: UP Visayas | I12: CFOS IA (DOST TGMPPEFET) | J12: N/A | K12: 9062227281 | L12: N/A | M12: atilanomaryantonette@gmail.com | N12: N/A
A13: 43874 | B13: Alvin M. Doroteo | C13: M | D13: CL-2020- | E13: 9 | F13: Completed | G13: Instructor I | H13: University of Antique | I13: COFES | J13: N/A | K13: 9272051528 | L13: N/A | M13: doroteoalvin@yahoo.com | N13: N/A
A14: 43902 | B14: Rema C. Sibonga | C14: F | D14: CL-2020- | E14: 10 | F14: Completed | G14: Early Career Researcher | H14: UP Visayas | I14: GlobalSeaweedSTARProejct, CFOS IA | J14: N/A | K14: 09171409960; 09985315320 | L14: N/A | M14: rcsibonga@gmail.com | N14: Institute of Aquaculture, College of Fisheries and Ocean Sciences, University of the Philippines Visayas, Miagao, 5023, Iloilo
A15: 43903 | B15: Karen Claire S. Ebreo | C15: F | D15: CL-2020- | E15: 11 | F15: Completed | G15: Research Assistant | H15: UP Visayas | I15: Taklong Barcoding Initiative, Marine Biodiversity and Evolution Lab, Division of Biological Sciences | J15: (033) 315 8160 | K15: 9174290778 | L15: N/A | M15: ksebreo@up.edu.ph | N15: Room 124, CAS Bldg., Division of Biological Sciences, College of Arts and Sciences, University of the Philippines Visayas, Miagao, Iloilo
A16: 43990 | B16: Kyle R. Castañares | C16: M | D16: CL-2020- | E16: 12 | F16: Completed | G16: University Research Associate I | H16: UP Visayas | I16: CFOS IA (DOST TGMPPEFET) | J16: N/A | K16: 9171669790 | L16: N/A | M16: kyleresmac@gmail.com | N16: IA-Hatchery Complex, University of the Philippines Visayas, Miagao 5023, Iloilo
A17: 43990 | B17: Angel Queenee D. Dequito | C17: F | D17: CL-2020- | E17: 13 | F17: Completed | G17: Assistant Professor/Project Leader | H17: UP Visayas | I17: CFOS IA (DOST TGMPPEFET) | J17: N/A | K17: 9177212519 | L17: N/A | M17: addequito@up.edu.ph | N17: CFOS-IA, UP Visayas, Miagao, Iloilo
A18: 44015 | B18: Nadalene Faith N. Cartago | C18: F | D18: CL-2020- | E18: 14 | F18: Completed | G18: MS Fisheries (Aquaculture) | H18: UP Visayas | I18: CFOS IA | J18: N/A | K18: 9452398275 | L18: N/A | M18: nadelenefaithcartago@yahoo.com | N18: 42 Quezon Street, Miagao, Iloilo
A19: 44015 | B19: Karl Angelo P. Tenizo | C19: M | D19: CL-2020- | E19: 15 | F19: Ongoing | G19: Science Research Assistant | H19: UP Visayas | I19: CFOS IA ("Ice-ice Project" | J19: N/A | K19: 9983085275 | L19: N/A | M19: kptenizo@up.edu.ph | N19: Nonato's Extension, Brgy. Baybay Norte, Miagao, Iloilo
A20: 44034 | B20: Gabrielle Troy A. Cuevas | C20: M | D20: CL-2020- | E20: 16 | F20: Completed | G20: Assistant Professor/Project Leader | H20: UP Visayas | I20: Department of Chemistry | J20: N/A | K20: 9953856717 | L20: N/A | M20: gacuevas@up.edu.ph | N20: Department of Chemistry, College of Arts and Sciences, UP Visayas
A21: 44034 | B21: Wilson F. Medrocillo | C21: M | D21: CL-2020- | E21: 17 | F21: Completed | G21: Research Assistant | H21: UP Visayas | I21: Department of Chemistry | J21: N/A | K21: 936981029 | L21: N/A | M21: wfmedrocillo@up.edu.ph | N21: RA Lounge, CAS Basement, College of Arts and Sciences, UP Visayas
A22: 44035 | B22: Leonilo F. Endoma | C22: M | D22: CL-2020- | E22: 18 | F22: Cancelled | G22: Faculty | H22: UP Visayas | I22: CFOS IFPT Chemistry Lab | J22: N/A | K22: 9152715677 | L22: N/A | M22: lfendoma@up.edu.ph
A23: 44048 | B23: Dominique P. Mediodia | C23: M | D23: CL-2020- | E23: 19 | F23: Completed | G23: Instructor/Project Leader | H23: UP Visayas | J23: N/A | K23: 9267259050 | L23: N/A | M23: dpmediodia@up.edu.ph | N23: UPV Museum of Natural Sciences, UP Visayas, Miagao, Iloilo 5023
A24: 44048 | B24: Ma. Novem Grace Ylayron | C24: F | D24: CL-2020- | E24: 20 | F24: Completed | G24: Research Assistant | H24: UP Visayas | I24: CFOS IMFO/MFPA Project | J24: N/A | K24: 9292671029 | L24: N/A | M24: maylayron@up.edu.ph | N24: UPV CFOS IMFO
A25: 44048 | B25: Carmelo del Castillo | C25: M | D25: CL-2020- | E25: 21 | F25: Ongoing | G25: Assistant Professor | H25: UP Visayas | I25: CFOS IA | J25: N/A | K25: 9177110107 | L25: N/A | M25: csdelcastillo@up.edu.ph | N25: UPV
A26: 44062 | B26: Pretty Lee Silva | C26: F | D26: CL-2020- | E26: 22 | F26: Cancelled | G26: Faculty | H26: UP Visayas | I26: SOTECH/MS Chem Eng (Diliman)
A27: 44131 | B27: Loina Henzel A. Delgado | C27: F | D27: CL-2020- | E27: 023 | F27: Completed | G27: Student Assistant | H27: Samar State University | I27: Taklong Barcoding Initiative, Marine Biodiversity and Evolution Lab, Division of Biological Sciences | J27: (033) 315 8160 | K27: 9300953925 | L27: N/A | M27: ladelgado1@up.edu.ph | N27: Room 124, CAS Bldg., Division of Biological Sciences, College of Arts and Sciences, University of the Philippines Visayas, Miagao, Iloilo
A28: 44168 | B28: Denise V. Miranda | C28: F | D28: CL-2020- | E28: 024 | F28: Ongoing | G28: University Research Associate I | H28: UP Visayas | I28: CFOS IA (DOST Ice-Ice | J28: N/A | K28: 09777305977 | L28: N/A | M28: dvmiranda@up.edu.ph | N28: #49 Tajanlangit St., Brgy. Tacas, Miagao, Iloilo
A29: 2021
A30: 44216 | B30: Alain C. Juayang | C30: M | D30: CL-2021- | E30: 25 | F30: Completed | G30: Section Head | H30: Corazon Locsin Montelibano Memorial Regional Hospital | I30: Molecular Laboratory | J30: N/A | K30: 09226942501 | L30: N/A | M30: alainjuayang@yahoo.com | N30: Molecular Laboratory, Corazon L. Montelibano Memorial Regional Hospital, Burgos-Lacson St., Bacolod City
A31: 44216 | B31: Jezreel Teruel Ywayan | C31: F | D31: CL-2021- | E31: 26 | F31: Completed | G31: Chief Medical Technologist | H31: Bacolod Queen of Mercy Hospital | I31: Molecular Laboratory | J31: N/A | K31: 09231531678 | L31: N/A | M31: jbtywayanmolecular2020@gmail.com | N31: Bacolod Queen of Mercy Hospital Molecular Laboratory, LN Eroreco Drive, Mandalagan, Bacolod City 6100
A32: 44250 | B32: Leni G. Yap-Dejeto | C32: F | D32: CL-2021- | E32: 27 | F32: Completed | G32: Professor 6 | H32: UPV Tacloban College | I32: Division of Natural Science and Mathematics | J32: +6353 3218299 | K32: +639368135357 | L32: 6353 3255108 | M32: lgyapdejeto@up.edu.ph | N32: UPV Tacloban College, Magsaysay Blvd., Tacloban City, Leyte 6500
A33: 44280 | B33: Dianne Frances Penuela | C33: F | D33: CL-2021- | E33: 28 | F33: Completed | G33: Science Research Assistant | H33: UP Visayas | I33: Division of Biological Sciences | J33: 323 2733 | K33: 09052565544 | L33: N/A | M33: dapenuela@up.edu.ph | N33: Brgy. Abangay, Dingle, Iloilo
A34: 44280 | B34: Roxanne Cabebe | C34: F | D34: CL-2021- | E34: 29 | F34: Completed | G34: Science Research Assistant | H34: UP Visayas | I34: Division of Biological Sciences | J34: N/A | K34: 09760511920 | L34: N/A | M34: racabebe@up.edu.ph | N34: Brgy. Mat-y, Miagao, Iloilo
A35: 44302 | B35: Albert C. Noblezada | C35: M | D35: CL-2021- | E35: 30 | F35: Completed | G35: MS Fisheries (Aquaculture) | H35: UP Visayas | I35: CFOS IA | J35: N/A | K35: 09165448358 | L35: N/A | M35: acnoblezada@up.edu.ph | N35: Brgy. Buenavista, Leon, Iloilo
A36: 44334 | B36: Arlene L . Avillanosa | C36: F | D36: CL-2021- | E36: 31 | F36: Ongoing | G36: Project Leader | H36: Western Philippines University | I36: WPU GeM-PHIL Project | J36: N/A | K36: 09278173880 | L36: N/A | M36: arlene.avillanosa@wpu.edu.ph | N36: Room 9, Second Floor (ABBA R&D Center), College of Fisheries and Aquatic Science (CFAS), WPU-Puerto Princesa Campus, Sta. Monica, Puerto Princesa City
A37: 44334 | B37: Reymart S. Dagaraga | C37: M | D37: CL-2021- | E37: 32 | F37: Ongoing | G37: University Research Associate | H37: Western Philippines University | I37: WPU GeM-PHIL Project | J37: N/A | K37: 09678700527 09475042638 09958698243 | L37: N/A | M37: gemphilproject@gmail.com | N37: Room 9, Second Floor (ABBA R&D Center), College of Fisheries and Aquatic Science (CFAS), WPU-Puerto Princesa Campus, Sta. Monica, Puerto Princesa City
A38: 44334 | B38: Jasper D. Pacho | C38: M | D38: CL-2021- | E38: 33 | F38: Ongoing | G38: Science Research Assistant | H38: Western Philippines University | I38: WPU GeM-PHIL Project | J38: N/A | K38: 09507960935 | L38: N/A | M38: jasperpacho181@gmail.com | N38: Room 9, Second Floor (ABBA R&D Center), College of Fisheries and Aquatic Science (CFAS), WPU-Puerto Princesa Campus, Sta. Monica, Puerto Princesa City
A39: 44382 | B39: Kristina Samantha Lacson | C39: F | D39: CL-2021- | E39: 34 | F39: Completed | G39: Research Assistant | H39: UP Visayas | I39: Department of Chemistry | J39: N/A | K39: 09561765997 | L39: N/A | M39: kblacson@up.edu.ph | N39: College of Arts and Sciences (CAS) Buidling, University of the Philippines Visayas, Miagao, Iloilo 5023
A40: 44382 | B40: Concepcion Ponce | C40: F | D40: CL-2021- | E40: 35 | F40: Completed | G40: Project Leader | H40: UP Visayas | I40: Department of Chemistry | J40: N/A | K40: 09951970469 | L40: N/A | M40: cpponce@upv.edu.ph | N40: College of Arts and Sciences (CAS) Buidling, University of the Philippines Visayas, Miagao, Iloilo 5023
...

Sheet PLEASE READ ME
A1: Column 1 | B1: INSTRUCTION FOR USE OF CLIENT RECORDS | C1: INSTRUCTION FOR USE OF PROJECT RECORDS | D1: INSTRUCTION FOR USE OF CHARGE SLIP/BILLING
A2: 1. The search bar is programmed for quick search of a client and the project(s) where he/she belongs to | B2: 1. The client records sheet serves as the masterlist of information of all transacting clients. | C2: 1. The Project records sheet contains the project that a client(s) belongs to. Some client may not belong to a certain project depending on the nature of their engagement. | D2: 1. The charge slip/billing sheet serves as a summary of all charge slip released to transacting clients.
A3: 2. Type the client's name under the 'SEARCH CLIENT NAME' cell to search for the information | B3: 2. Before the service starts, all new transacting client must be given the following forms to process their information in the client records sheet: - Client Information Sheet (CIS): VSF-LF-CIS-v003 - Client Conforme (CC) | C3: 2. Choose/type the client's name from the drop down under the 'Client Name' column. If client name is not found, it means that the client is missing in the client records sheet. Input information of the client first before accomplishing the project records sheet. | D3: 2. A charge slip is released once the service has been rendered or the client has requested it in advance.
A4: 3. Information includes project/s attached to the client and charging/billing paid | B4: 3. All information in the client records sheet must be provided by the client as this will be carried over to different database requiring the same information. Ask client not to leave any information blank. | C4: 3. All information in the project records sheet must be provided by the client through the CIS. Once forms are accomplished, input ALL information in the sheet. PLEASE DO NOT LEAVE ANY INFORMATION BLANK. | D4: 3. The columns E to H are automated. Choose/type the client's name from the drop down in the 'Client Name' column to generate information of columns E to H. Input all other information manually. PLEASE DO NOT LEAVE ANY INFORMATION BLANK.
B5: 4. Once forms are accomplished, input the client's information in the sheet. PLEASE DO NOT LEAVE ANY INFORMATION BLANK. | C5: 4. Follow this format for assigning Project ID: P-YYYY-XXX; (XXX is continuous the next year) | D5: 4. Follow this format for assigning Charge Slip No.: CS-YYYY-XXX (XXX is non-continuous the next year. Start with 001 every start of the year)
B6: 5. Follow this format for assigning Client ID: CL-YYYY-XXX; (XXX is continuous the next year) | D6: 5. There are instances that a charge slip may not push through until payment due to corrections, cancellation of service, and/or the service requested did not push through. During this instance, mark the released charge slip as 'Cancelled' to avoid including it in the total of revenues during reports.
D7: 6. Regularly update the status of each charging to know if payment has already been made.
D8: LEGEND: DV. No. - Disbursement Voucher Number; Proof of payment for payments made through procurement process. OR No. - Official Receipt Number provided by the cash office once OR has been released

Sheet SEARCH BAR
D1: a
B2: SEARCH CLIENT NAME
B3: aye m
A5: Client Name | B5: Client ID Number | C5: Affiliation (Department and Institution Name and Address) | D5: Sex | E5: Designation | F5: Email Address | G5: Mobile Number
A6: =IFERROR(__xludf.DUMMYFUNCTION("FILTER('Client ID Records_v2'!D:J, SEARCH(B3,'Client ID Records_v2'!D:D))"),"Aye Mee Bartocillo") -> Aye Mee Bartocillo | B6: =IFERROR(__xludf.DUMMYFUNCTION("""COMPUTED_VALUE"""),"CL-2025-297") -> CL-2025-297 | C6: =IFERROR(__xludf.DUMMYFUNCTION("""COMPUTED_VALUE"""),"Biology Department, Siliman University, Dumaguete City Negros Oriental") -> Biology Department, Siliman University, Dumaguete City Negros Oriental | D6: =IFERROR(__xludf.DUMMYFUNCTION("""COMPUTED_VALUE"""),"F") -> F | E6: =IFERROR(__xludf.DUMMYFUNCTION("""COMPUTED_VALUE"""),"Balik Scientist") -> Balik Scientist | F6: =IFERROR(__xludf.DUMMYFUNCTION("""COMPUTED_VALUE"""),"ayefbartocillo@su.edu.ph") -> ayefbartocillo@su.edu.ph | G6: =IFERROR(__xludf.DUMMYFUNCTION("""COMPUTED_VALUE"""),9.274310611E9) -> 9274310611
A12: Project Lead/ Contact Person | B12: Project Number | C12: Project Title | D12: Project Tag | E12: Status
A13: =IFERROR(__xludf.DUMMYFUNCTION("FILTER('Project Records_v2'!E:I, SEARCH(B3,'Project Records_v2'!E:E))"),"#N/A") -> #N/A
A18: Charge Slip No. (CS-yyyy-xxx) | B18: Client Name | C18: Amount | D18: Status
A19: =IFERROR(__xludf.DUMMYFUNCTION("FILTER('Charge SlipBilling'!C:F, SEARCH(B3,'Charge SlipBilling'!D:D))"),"CS-2025-046") -> CS-2025-046 | B19: =IFERROR(__xludf.DUMMYFUNCTION("""COMPUTED_VALUE"""),"Aye Mee Bartocillo") -> Aye Mee Bartocillo | C19: =IFERROR(__xludf.DUMMYFUNCTION("""COMPUTED_VALUE"""),28863.03) -> 28863.03 | D19: =IFERROR(__xludf.DUMMYFUNCTION("""COMPUTED_VALUE"""),"PAID") -> PAID

Sheet Client ID Records_v2
A1: Year | B1: Date Received | C1: Status | D1: Client Name | E1: Client ID Number | F1: Affiliation (Department and Institution Name and Address) | G1: Sex | H1: Designation | I1: Email Address | J1: Mobile Number
A2: 2019 | B2: 43508 | C2: Ongoing | D2: PGC VISAYAS | E2: CL-2019-000 | F2: PGC Visayas Laboratories Room 205, 2nd Floor Regional Research Center University of the Philippines Visayas Brgy. Mambatad, Miagao, Iloilo 5023 | G2: N/A | H2: Others | I2: pgc.upvisayas@up.edu.ph
A3: 2020 | B3: 43873 | C3: Completed | D3: Nowena S. Solidum | E3: CL-2020-001 | F3: Fishery Department, Capiz State University - Dayao Satellite College, Dayao, Roxas City, Capiz | G3: F | H3: Faculty | I3: nowena_solidum@yahoo.com | J3: 9983950535
A4: 2020 | B4: 43873 | C4: Completed | D4: Marissa C. Naorbe | E4: CL-2020-002 | F4: Fishery Department, Capiz State University - Dayao Satellite College, Dayao, Roxas City, Capiz | G4: F | H4: Faculty | I4: castromarissa99@gmail.com | J4: 9506798777
A5: 2020 | B5: 43873 | C5: Completed | D5: Shirleen Grace Brillantes | E5: CL-2020-003 | F5: Samar State University - Mercedes, Mercedes, Catbalogan City, Samar 6700 | G5: F | H5: Faculty | I5: sweetbrillantes@gmail.com | J5: 9177145364
A6: 2020 | B6: 43873 | C6: Completed | D6: Irene Jean C. Lagumbay | E6: CL-2020-004 | F6: Samar State University - Mercedes, Mercedes, Catbalogan City, Samar 6700 | G6: F | H6: Faculty | I6: irenelagumbay95@gmail.com | J6: 9165866013
A7: 2020 | B7: 43873 | C7: Completed | D7: Rhodmar D. Panis | E7: CL-2020-005 | F7: Samar State University - Mercedes, Mercedes, Catbalogan City, Samar 6700 | G7: M | H7: Researcher/Technical Assistant | I7: rhodmar.divino@ssu.up.edu.ph | J7: 9056728581
A8: 2020 | B8: 43873 | C8: Completed | D8: Jay T. Torrefiel | E8: CL-2020-006 | F8: UPV Tacloban College | G8: M | H8: Faculty | I8: jattorrefiel@gmail.com | J8: 9058848900
A9: 2020 | B9: 43873 | C9: Completed | D9: Rhyzz Jane Balinos | E9: CL-2020-007 | F9: CFOS IA (DOST TGMPPEFET) | G9: F | H9: Researcher/Technical Assistant | I9: rhyzz.jane@gmail.com | J9: 9666553130
A10: 2020 | B10: 43873 | C10: Completed | D10: Mary Antonette F. Atilano | E10: CL-2020-008 | F10: CFOS IA (DOST TGMPPEFET) | G10: F | H10: Researcher/Technical Assistant | I10: atilanomaryantonette@gmail.com | J10: 9062227281
A11: 2020 | B11: 43874 | C11: Completed | D11: Alvin M. Doroteo | E11: CL-2020-009 | F11: COFES, University of Antique | G11: M | H11: Faculty | I11: doroteoalvin@yahoo.com | J11: 9272051528
A12: 2020 | B12: 43902 | C12: Completed | D12: Rema C. Sibonga | E12: CL-2020-010 | F12: Institute of Aquaculture, College of Fisheries and Ocean Sciences, University of the Philippines Visayas, Miagao, 5023, Iloilo | G12: F | H12: Researcher/Technical Assistant | I12: rcsibonga@gmail.com | J12: 09171409960; 09985315320
A13: 2020 | B13: 43903 | C13: Completed | D13: Karen Claire S. Ebreo | E13: CL-2020-011 | F13: Room 124, CAS Bldg., Division of Biological Sciences, College of Arts and Sciences, University of the Philippines Visayas, Miagao, Iloilo | G13: F | H13: Researcher/Technical Assistant | I13: ksebreo@up.edu.ph | J13: 9174290778
A14: 2020 | B14: 43990 | C14: Completed | D14: Kyle R. Castañares | E14: CL-2020-012 | F14: IA-Hatchery Complex, University of the Philippines Visayas, Miagao 5023, Iloilo | G14: M | H14: Researcher/Technical Assistant | I14: kyleresmac@gmail.com | J14: 9171669790
A15: 2020 | B15: 43990 | C15: Completed | D15: Angel Queenee D. Dequito | E15: CL-2020-013 | F15: Institute of Aquaculture, College of Fisheries and Ocean Sciences, University of the Philippines Visayas, Miagao, 5023, Iloilo | G15: F | H15: Project Leader | I15: addequito@up.edu.ph | J15: 9177212519
A16: 2020 | B16: 44015 | C16: Completed | D16: Nadalene Faith N. Cartago | E16: CL-2020-014 | F16: Institute of Aquaculture, College of Fisheries and Ocean Sciences, University of the Philippines Visayas, Miagao, 5023, Iloilo | G16: F | H16: MS Student | I16: nadelenefaithcartago@yahoo.com | J16: 9452398275
A17: 2020 | B17: 44015 | C17: Ongoing | D17: Karl Angelo P. Tenizo | E17: CL-2020-015 | F17: Institute of Aquaculture, College of Fisheries and Ocean Sciences, University of the Philippines Visayas, Miagao, 5023, Iloilo | G17: M | H17: Researcher/Technical Assistant | I17: kptenizo@up.edu.ph | J17: 9983085275
A18: 2020 | B18: 44034 | C18: Completed | D18: Gabrielle Troy A. Cuevas | E18: CL-2020-016 | F18: Department of Chemistry, College of Arts and Sciences, UP Visayas | G18: M | H18: Project Leader | I18: gacuevas@up.edu.ph | J18: 9953856717
A19: 2020 | B19: 44034 | C19: Completed | D19: Wilson F. Medrocillo | E19: CL-2020-017 | F19: RA Lounge, CAS Basement, College of Arts and Sciences, UP Visayas | G19: M | H19: Researcher/Technical Assistant | I19: wfmedrocillo@up.edu.ph | J19: 936981029
A20: 2020 | B20: 44035 | C20: Cancelled | D20: Leonilo F. Endoma | E20: CL-2020-018 | F20: Institute of Fish Processing Technology, College of Fisheries and Ocean Sciences, University of the Philippines Visayas | G20: M | H20: Faculty | I20: lfendoma@up.edu.ph | J20: 9152715677
A21: 2020 | B21: 44048 | C21: Completed | D21: Dominique P. Mediodia | E21: CL-2020-019 | F21: Institute of Marine Fisheries and Oceanology, College of Fisheries and Ocean Sciences, University of the Philippines Visayas | G21: M | H21: Project Leader | I21: dpmediodia@up.edu.ph | J21: 9267259050
A22: 2020 | B22: 44048 | C22: Completed | D22: Ma. Novem Grace Ylayron | E22: CL-2020-020 | F22: Institute of Marine Fisheries and Oceanology, College of Fisheries and Ocean Sciences, University of the Philippines Visayas | G22: F | H22: Researcher/Technical Assistant | I22: maylayron@up.edu.ph | J22: 9292671029
A23: 2020 | B23: 44048 | C23: Ongoing | D23: Carmelo del Castillo | E23: CL-2020-021 | F23: Institute of Aquaculture, College of Fisheries and Ocean Sciences, University of the Philippines Visayas, Miagao, 5023, Iloilo | G23: M | H23: Faculty | I23: csdelcastillo@up.edu.ph | J23: 9177110107
A24: 2020 | B24: 44062 | C24: Cancelled | D24: Pretty Lee Silva | E24: CL-2020-022 | F24: School of Technology, University of the Philippines Visayas, Miagao, 5023, Iloilo | G24: F | H24: Faculty
A25: 2020 | B25: 44131 | C25: Completed | D25: Loina Henzel A. Delgado | E25: CL-2020-023 | F25: Room 124, CAS Bldg., Division of Biological Sciences, College of Arts and Sciences, University of the Philippines Visayas, Miagao, Iloilo | G25: F | H25: Researcher/Technical Assistant | I25: ladelgado1@up.edu.ph | J25: 9300953925
A26: 2020 | B26: 44168 | C26: Ongoing | D26: Denise V. Miranda | E26: CL-2020-024 | F26: Institute of Aquaculture, College of Fisheries and Ocean Sciences, University of the Philippines Visayas, Miagao, 5023, Iloilo | G26: F | H26: Researcher/Technical Assistant | I26: dvmiranda@up.edu.ph | J26: 9777305977
A27: 2021 | B27: 44216 | C27: Completed | D27: Alain C. Juayang | E27: CL-2021-025 | F27: Molecular Laboratory, Corazon L. Montelibano Memorial Regional Hospital, Burgos-Lacson St., Bacolod City | G27: M | H27: Staff | I27: alainjuayang@yahoo.com | J27: 9226942501
A28: 2021 | B28: 44216 | C28: Completed | D28: Jezreel Teruel Ywayan | E28: CL-2021-026 | F28: Bacolod Queen of Mercy Hospital Molecular Laboratory, LN Eroreco Drive, Mandalagan, Bacolod City 6100 | G28: F | H28: Staff | I28: jbtywayanmolecular2020@gmail.com | J28: 9231531678
A29: 2021 | B29: 44250 | C29: Completed | D29: Leni G. Yap-Dejeto | E29: CL-2021-027 | F29: UPV Tacloban College, Magsaysay Blvd., Tacloban City, Leyte 6500 | G29: F | H29: Faculty | I29: lgyapdejeto@up.edu.ph | J29: 639368135357
A30: 2021 | B30: 44280 | C30: Completed | D30: Dianne Frances Penuela | E30: CL-2021-028 | F30: Division of Biological Sciences, College of Arts and Sciences, University of the Philippines Visayas, Miagao, Iloilo | G30: F | H30: Researcher/Technical Assistant | I30: dapenuela@up.edu.ph | J30: 9052565544
A31: 2021 | B31: 44280 | C31: Completed | D31: Roxanne Cabebe | E31: CL-2021-029 | F31: Institute of Marine Fisheries and Oceanology, College of Fisheries and Ocean Sciences, University of the Philippines Visayas | G31: F | H31: Researcher/Technical Assistant | I31: racabebe@up.edu.ph | J31: 9760511920
A32: 2021 | B32: 44302 | C32: Completed | D32: Albert C. Noblezada | E32: CL-2021-030 | F32: Institute of Aquaculture, College of Fisheries and Ocean Sciences, University of the Philippines Visayas, Miagao, 5023, Iloilo | G32: M | H32: MS Student | I32: acnoblezada@up.edu.ph | J32: 9165448358
A33: 2021 | B33: 44334 | C33: Ongoing | D33: Arlene L . Avillanosa | E33: CL-2021-031 | F33: Room 9, Second Floor (ABBA R&D Center), College of Fisheries and Aquatic Science (CFAS), WPU-Puerto Princesa Campus, Sta. Monica, Puerto Princesa City | G33: F | H33: Project Leader | I33: arlene.avillanosa@wpu.edu.ph | J33: 9278173880
A34: 2021 | B34: 44334 | C34: Ongoing | D34: Reymart S. Dagaraga | E34: CL-2021-032 | F34: Room 9, Second Floor (ABBA R&D Center), College of Fisheries and Aquatic Science (CFAS), WPU-Puerto Princesa Campus, Sta. Monica, Puerto Princesa City | G34: M | H34: Researcher/Technical Assistant | I34: gemphilproject@gmail.com | J34: 09678700527 09475042638 09958698243
A35: 2021 | B35: 44334 | C35: Ongoing | D35: Jasper D. Pacho | E35: CL-2021-033 | F35: Room 9, Second Floor (ABBA R&D Center), College of Fisheries and Aquatic Science (CFAS), WPU-Puerto Princesa Campus, Sta. Monica, Puerto Princesa City | G35: M | H35: Researcher/Technical Assistant | I35: jasperpacho181@gmail.com | J35: 9507960935
A36: 2021 | B36: 44382 | C36: Completed | D36: Kristina Samantha Lacson | E36: CL-2021-034 | F36: College of Arts and Sciences (CAS) Buidling, University of the Philippines Visayas, Miagao, Iloilo 5023 | G36: F | H36: Researcher/Technical Assistant | I36: kblacson@up.edu.ph | J36: 9561765997
A37: 2021 | B37: 44382 | C37: Completed | D37: Concepcion Ponce | E37: CL-2021-035 | F37: College of Arts and Sciences (CAS) Buidling, University of the Philippines Visayas, Miagao, Iloilo 5023 | G37: F | H37: Project Leader | I37: cpponce@upv.edu.ph | J37: 9951970469
A38: 2021 | B38: 44435 | C38: Cancelled | D38: Carolyn T. Mejares | E38: CL-2021-036 | F38: School of Technology, University of the Philippines Visayas, Miagao, Iloilo | G38: F | H38: Faculty | I38: ctmejares@up.edu.ph | J38: 9174804428
A39: 2022 | B39: 44580 | C39: Cancelled | D39: Rowena E. Cadiz | E39: CL-2022-037 | F39: Institute of Aquaculutre, College of Fisheries and Ocean Science, University of the Philippines Visayas, Miagao, Iloilo | G39: F | H39: Researcher/Technical Assistant | I39: recadiz@up.edu.ph
A40: 2022 | B40: 44622 | C40: Ongoing | D40: Eric Zeus C. Rizo | E40: CL-2022-038 | F40: Division of Biological Sciences, College of Arts and Sciences, University of the Philippines Visayas, Miagao, Iloilo | G40: M | H40: Project Leader | I40: ecrizo@up.edu.ph | J40: 9153101800
...

Sheet Project Records_v2
A1: Year | B1: Start date | C1: End date | D1: Client Names | E1: Project Lead/ Contact Person | F1: Project Number | G1: Project Title | H1: Project Tag | I1: Status | J1: Sending Institution | K1: Funding Category | L1: Funding Institution | M1: Service Requested | N1: Personnel Assigned | O1: Notes
A2: 2019 | B2: 43525 | D2: N/A | E2: PGC VISAYAS | F2: P-2019-000 | G2: PGC VISAYAS SATELLITE FACILITY | H2: PGCV | I2: Ongoing | J2: N/A | K2: In-House | L2: DOST-PCHRD | M2: N/A
A3: 2020 | B3: 43903 | C3: 44196 | D3: N/A | E3: Rema C. Sibonga | F3: P-2020-001 | G3: Global Seaweed STAR Project | H3: GSStar | I3: Completed | J3: UP System | K3: External | L3: UK Research and Innovation - Global Challenges Research Fund (UKRI-GCRF) | M3: Equipment Use | N3: Ma Carmel Javier
A4: 2020 | B4: 43903 | C4: 44408 | D4: Loina Henzel A. Delgado | E4: Karen Claire S. Ebreo | F4: P-2020-002 | G4: Taklong Barcoding Initiative | H4: TBI | I4: Completed | J4: UP System | K4: External | L4: N/A | M4: Equipment Use | N4: Ma Carmel Javier
A5: 2020 | B5: 43990 | C5: 44316 | D5: Kyle R. Castañares Mary Antonette F. Atilano | E5: Angel Queenee D. Dequito | F5: P-2020-003 | G5: Transcriptome and Gut Metagenome Profile of Penaeus vannamei Exposed to Fluctuating Environmental Temperatures | H5: TGMPPEFET | I5: Completed | J5: UP System | K5: External | L5: DOST-PCAARRD | M5: Equipment Use | N5: Jasmine Velo
A6: 2020 | B6: 44015 | C6: 44347 | E6: Nadelene Faith N. Cartago | F6: P-2020-004 | G6: Transcriptional Response of Selected Genes of the Green Mussel (Perna viridis) Exposed to Heat Stress | H6: Cartago | I6: Completed | J6: UP System | K6: External | L6: DOST-ASTHRDP | M6: Equipment Use | N6: Ma Carmel Javier
A7: 2020 | B7: 44034 | D7: Denise V. Miranda | E7: Karl Angelo P. Tenizo | F7: P-2020-005 | G7: Transcriptome and metabolome profiling of seaweeds to elucidate "ice-ice" disease and epiphyte infestation mechanisms | H7: Ice-Ice | I7: Ongoing | J7: UP System | K7: External | L7: DOST-PCAARRD | M7: Equipment Use | N7: Ma Carmel Javier
A8: 2020 | B8: 44034 | C8: 44742 | D8: Wilson F. Medrocillo | E8: Gabrielle Troy A. Cuevas | F8: P-2020-006 | G8: Purification and Characterization of Linamarase from Lakan-1 and Java Variety Cassava (Manihot esculenta Crantz) | H8: Cuevas | I8: Completed | J8: UP System | K8: External | L8: UPV In-House Project | M8: Equipment Use | N8: Ma Carmel Javier
A9: 2020 | B9: 44035 | E9: Leonilo F. Endoma | F9: P-2020-007 | G9: Instructional videos for Fish 111, Fish 236, Fish 238, Fish 321 | H9: Endoma | I9: Cancelled | J9: UP System | K9: External | L9: N/A | M9: Equipment Use | N9: Jasmine Velo
A10: 2020 | B10: 44048 | C10: 44620 | D10: Ma. Novem Grace Ylayron Carmelo del Castillo | E10: Dominique P. Mediodia | F10: P-2020-008 | G10: Marine Fisheries Assessment of Panay: Building Local Fisheries Information through Research Capability Enhancement on Higher Education Insitutions | H10: Panay Marfish Project | I10: Completed | J10: UP System | K10: External | L10: CHED | M10: Equipment Use | N10: Jasmine Velo
A11: 2020 | B11: 44062 | E11: Pretty Lee Silva | F11: P-2020-009 | G11: MS in Chemical Engineering | H11: Silva | I11: Cancelled | J11: UP System | K11: External | L11: N/A | M11: Equipment Use | N11: Marj Gem Bunda-Fajunio
A12: 2021 | B12: 44250 | C12: 44377 | E12: Leni G. Yap-Dejeto | F12: P-2021-010 | G12: c/o UP Visayas Tacloban College | H12: Glycogen | I12: Completed | J12: SUC/HEI | K12: External | L12: N/A | M12: Laboratory Services | N12: Jasmine Velo
A13: 2021 | B13: 44280 | C13: 44882 | D13: Roxanne Cabebe | E13: Dianne Frances Penuela | F13: P-2021-011 | G13: DNA barcoding of fishes from Western Visayas, Philippines | H13: DNA Barcoding | I13: Completed | J13: UP System | K13: External | L13: CHED | M13: Equipment Use
A14: 2021 | B14: 44302 | C14: 44681 | E14: Albert C. Noblezada | F14: P-2021-012 | G14: Population Structure of Green Mussel (Perna viridis) in Panay Island, Philippines using D-loop Sequences | H14: Noblezada | I14: Completed | J14: UP System | K14: External | L14: DOST-ASTHRDP Thesis Grant | M14: Equipment Use
A15: 2021 | B15: 44334 | D15: Reymart S. Dagaraga Jasper D. Pacho | E15: Arlene L . Avillanosa | F15: P-2021-013 | G15: Genetic Characterization of Macrobrachium populations in the Philippines for broodstock development and seed production | H15: GeM-PHIL | I15: Ongoing | J15: SUC/HEI | K15: External | L15: DOST-PCAARRD | M15: Laboratory Services | N15: Nadelene Faith Cartago
A16: 2021 | B16: 44382 | C16: 44553 | D16: Kristina Samantha Lacson | E16: Concepcion Ponce | F16: P-2021-014 | G16: Pre-commercialization of Microwave Extracted Pectin from Waste Calamansi Peels | H16: Calamansi Project | I16: Completed | J16: SUC/HEI | K16: External | L16: CHED | M16: Retail Sales | N16: N/A
A17: 2021 | B17: 44435 | E17: Carolyn T. Mejares | F17: P-2021-015 | G17: Effect of high temperature treatments on buffalo milk and buffalo bovine milk blends | H17: Mejares | I17: Cancelled | J17: UP System | L17: N/A | N17: N/A
A18: 2022 | B18: 44579 | E18: Rowena E. Cadiz | F18: P-2022-016 | G18: Development of immunoactive and growth promoting AquaFeed additive from Ulva seaweed | H18: AquaFeed | I18: Cancelled | J18: UP System | K18: External | L18: DOST-PCAARRD | M18: Equipment Use | N18: N/A
A19: 2022 | B19: 44622 | D19: Shea Kathleen P. Guinto | E19: Eric Zeus C. Rizo | F19: P-2022-017 | G19: Development of a Water Quality Biological Monitoring Protocol using Genetic, Phylogenetic and Functional Diversity on Freshwater Zooplankton Communitites in Inland Waters of Panay Island, Philippines | H19: PFZ | I19: Ongoing | J19: UP System | K19: External | L19: DOST-PCIEERD | M19: Equipment Use | N19: Nadelene Faith Cartago
A20: 2022 | B20: 44622 | C20: 44865 | E20: Rother M. Gaudiel | F20: P-2022-018 | G20: Fishery and Some Aspects on the Biology and Ecology of the Sergestid Shrimp, Acetes, in Miagao, Iloilo | H20: RGaudiel | I20: Completed | J20: UP System | K20: External | L20: DOST-ASTHRDP Thesis Grant | M20: Equipment Use | N20: Nadelene Faith Cartago
A21: 2022 | B21: 44624 | C21: 44687 | E21: John Rey F. Rasgo | F21: P-2022-019 | G21: Genetic Marker Assessment of 12s and 18s of Kappaphycus striatus collected in Palawan | H21: JRRasgo | I21: Completed | J21: UP System | K21: External | L21: c/o Global Seaweed STAR Project | M21: Equipment Use | N21: Nadelene Faith Cartago
A22: 2022 | B22: 44628 | C22: 44986 | E22: Luke Dranoel D. Atencio | F22: P-2022-020 | G22: ESKAPE Pathogens in Intensive Care Unit from a Tertiary Healthcare Setting | H22: LDAtencio | I22: Completed | J22: SUC/HEI | K22: External | L22: N/A | M22: Equipment Use | N22: Jasmine Velo
A23: 2022 | B23: 44634 | C23: 44687 | E23: Whelver N. Surnido | F23: P-2022-021 | G23: Dynamics of the Epibacterial Community Structure and Composition of Kappaphycus alvarezii in Response to Thermal-induced Ice-ice Disease | H23: WNSurnido | I23: Completed | J23: UP System | K23: External | L23: c/o Ice-ice Project | M23: Equipment Use | N23: Ma Carmel Javier
A24: 2022 | B24: 44644 | C24: 44712 | E24: Kingsley John de los Santos | F24: P-2022-022 | G24: Assessment of Anthropogenic Marine Debris and Mangrove Forest Health in Iloilo Strait, Western Visayas, Philippines | H24: KDSantos | I24: Completed | J24: UP System | K24: External | L24: DOST-ASTHRDP Thesis Grant | M24: Retail Sales | N24: N/A
A25: 2022 | B25: 44645 | C25: 44727 | E25: Karl C. Abismo | F25: P-2022-023 | G25: Assessment of Antimicrobial Activitiy of Selected Fungi from Tilapia Greenwater Technology Against Vibrio parahaemolyticus in Blood Cockle, Anadara granosa | H25: KCAbismo | I25: Completed | J25: UP System | K25: External | L25: DOST Thesis Grant | M25: Equipment Use | N25: Jasmine Velo
A26: 2022 | B26: 44680 | C26: 45016 | E26: Benedict Maralit | F26: P-2022-024 | G26: Sequencing and Analysis of SARS-CoV-2 genomes in swab specimens collected by subnational / DOH-accredited COVID-19 laboratories in the Philippines from March to October 2020 | H26: Retrospective Biosurveillance | I26: Completed | J26: UP System | K26: External | L26: PGC Visayas | M26: Equipment Use | N26: N/A
A27: 2022 | B27: 44680 | E27: Philip Alviola | F27: P-2022-025 | G27: Molecular detection of Henipa and Coronavirus in Flying Fox (Order Chiroptera: Family Pteropodidae) roost within First Gas Plant Site, Batangas City | H27: Bats | I27: Ongoing | J27: UP System | K27: In-House | L27: PGC Visayas | M27: Equipment Use | N27: Jasmine Velo
A28: 2022 | B28: 44682 | E28: Persie Persie Mark Sienes | F28: P-2022-026 | G28: Whole Genome Sequencing of the Philippine spotted deer (Rusa alfredi) | H28: PGCV_Deer WGS | I28: Ongoing | J28: SUC/HEI | K28: In-House | L28: PGC Visayas | M28: Laboratory Services | N28: Ma Carmel Javier
A29: 2022 | B29: 44682 | C29: 45229 | E29: Beverly T. Jaspe | F29: P-2022-027 | G29: Genomic variations among different (meta) populations of oriental angelwing clam (Pholas orientalis) in the Western Visayas, Philippines: basis for conservation breeding program | H29: Pholas | I29: Completed | J29: SUC/HEI | K29: External | L29: DOST-NRCP NSTEP | M29: Equipment Use | N29: Ma Carmel Javier
A30: 2022 | B30: 44718 | C30: 44926 | E30: Camille Rose T. Mueda | F30: P-2022-028 | G30: Metagenomic Characterization of Oil-degrading Microbial Communities from Slipper-shaped Oyster (Magallana bilineata) in Oil-contaminated Areas along Iloilo Strait, Philippines | H30: Mueda | I30: Completed | J30: UP System | K30: External | L30: PGC Visayas | M30: Equipment Use | N30: Ma Carmel Javier
A31: 2022 | B31: 44725 | D31: Kneessa Louie G. Dato-on | E31: Therese Javellana | F31: P-2022-029 | G31: Isolation, Characterization and Phylogenetic identification of Thraustochytrids from mangrove habitats around Panay Island, Philippines | H31: Thrausto | I31: Ongoing | J31: UP System | K31: In-House | L31: PGC Visayas | M31: Laboratory Services | N31: kgdatoon@up.edu.ph
A32: 2022 | B32: 44729 | C32: 44773 | E32: Zeth Rodario Bebit | F32: P-2022-030 | G32: Marine Fisheries Assessment of Panay: Building Local Fisheries Information through Research Capability Enhancement in HEIs Component 3: Chemical Composition of Marine Fishes – Leverage Research Project (SP20-14) | H32: Bebit | I32: Completed | J32: UP System | K32: External | L32: CHED | M32: Equipment Use | N32: Ma Carmel Javier
A33: 2022 | B33: 44754 | C33: 44773 | E33: Angel Queenee D. Dequito | F33: P-2022-031 | G33: Transcriptome and Gut Metagenome Profile of Penaeus vannamei Exposed to Fluctuating Environmental Temperatures | H33: TGMPPEFET | I33: Completed | J33: UP System | K33: External | L33: DOST-PCAARRD | M33: Equipment Use | N33: Ma Carmel Javier
A34: 2022 | B34: 44763 | C34: 45107 | D34: Isabel Grace Gatpatan | E34: Rhudith Cabulong | F34: P-2022-032 | G34: Diversity and screening of culturable cellulytic microorganisms from mangrove forests, natural parks, paddy field, and sugar plantation in Panay Island, Philippines | H34: Cabulong, (OM,CM) | I34: Completed | J34: UP System | K34: In-House | L34: UPV Regular In-House Research (RIR) | M34: Laboratory Services | N34: Jasmine Velo
A35: 2022 | B35: 44835 | D35: Frenche B. Hechanova | E35: Rommel Gestuveo | F35: P-2022-033 | G35: Development of Novel Antiviral Compounds against Arthropod-borne Viruses | H35: DeNoVac | I35: Ongoing | J35: UP System | K35: External | L35: DOST-DST JRP | M35: Equipment Use | N35: Ma Carmel Javier
A36: 2022 | B36: 44859 | D36: Cezarie L. Golingay Ella Marie E. Villaruz Antoniette Lorain Z. Dimaano Arnel Adrian Rara | E36: Jade G. Pahila | F36: P-2022-034 | G36: Production and evaluation of Dried Microalgal Biomass for improved shelf life and product diversification | H36: Microalgae | I36: Completed | J36: UP System | K36: External | L36: DOST-PCAARD | M36: Equipment Use | N36: Jasmine Velo
A37: 2022 | B37: 44902 | C37: 45107 | E37: Pauline Anne Lamela | F37: P-2022-035 | G37: Isolation, Characterization, And Identification of Plastic-Degrading Bacteria From Bago City Landfill, Negros Occidental, Philippines | H37: Lamela | I37: Completed | J37: UP System | K37: External | L37: N/A | M37: Laboratory Services | N37: Nadelene Faith Cartago
A38: 2022 | B38: 44910 | C38: 45069 | D38: Emelyn Joy Mameloco Edcel T. Resano | E38: Raymond Cabarles | F38: P-2022-036 | G38: MS Aqua Fish 219 (Advanced Genetics) | H38: Cabarles et al | I38: Completed | J38: UP System | K38: In-House | L38: N/A | M38: Laboratory Services | N38: Jasmine Velo
A39: 2023 | B39: 44964 | E39: Dr. Sitti Zayda Halun | F39: P-2023-037 | G39: Amplicon Sequencing of Seaweed | H39: Halun | I39: Ongoing | J39: SUC/HEI | K39: External | L39: MSU TCTO | M39: Laboratory Services | N39: Nadelene Faith Cartago
A40: 2023 | B40: 44993 | C40: 45069 | E40: PGC Visayas | F40: P-2023-038 | G40: Molecular identification of Dugong (Batch 1) | H40: Dugong - Miagao | I40: Completed | J40: UP System | K40: In-House | L40: PGC Visayas | M40: Laboratory Services, Bioinformatics Analysis | N40: N/A
...

Sheet Charge SlipBilling
A1: Year | B1: Date | C1: Charge Slip No. (CS-yyyy-xxx) | D1: Client Name | E1: Amount | F1: Status | G1: Client ID | H1: Address | I1: Project/Training Request No. | J1: Payment For (Project/Training Title) | K1: Service Requested | L1: Service Details | M1: R&D Category | N1: DV No. | O1: OR No. | P1: Date of OR | Q1: Notes
A2: 2020 | B2: 44176 | C2: CS-2020-12-001 | D2: Dominique P. Mediodia | E2: 8597.6 | F2: PAID | G2: =IFERROR(VLOOKUP(D2,'Client ID Records_v2'!D:E, 2, FALSE), "") -> CL-2020-019 | H2: =IFERROR(VLOOKUP(G2,'Client ID Records_v2'!E:F, 2, FALSE), "") -> Institute of Marine Fisheries and Oceanology, College of Fisheries and Ocean Sciences, University of the Philippines Visayas | I2: =IFERROR(VLOOKUP(D2,'Project Records_v2'!E:F, 2, FALSE), "") -> P-2020-008 | J2: =IFERROR(VLOOKUP(I2,'Project Records_v2'!F:G, 2, FALSE), "") -> Marine Fisheries Assessment of Panay: Building Local Fisheries Information through Research Capability Enhancement on Higher Education Insitutions | K2: Equipment Use | L2: N/A | M2: Laboratory Service | N2: TF-2020-12-09150
A3: 2021 | B3: 44258 | C3: CS-2021-03-002 | D3: Dominique P. Mediodia | E3: 7335.24 | F3: PAID | G3: =IFERROR(VLOOKUP(D3,'Client ID Records_v2'!D:E, 2, FALSE), "") -> CL-2020-019 | H3: =IFERROR(VLOOKUP(G3,'Client ID Records_v2'!E:F, 2, FALSE), "") -> Institute of Marine Fisheries and Oceanology, College of Fisheries and Ocean Sciences, University of the Philippines Visayas | I3: =IFERROR(VLOOKUP(D3,'Project Records_v2'!E:F, 2, FALSE), "") -> P-2020-008 | J3: =IFERROR(VLOOKUP(I3,'Project Records_v2'!F:G, 2, FALSE), "") -> Marine Fisheries Assessment of Panay: Building Local Fisheries Information through Research Capability Enhancement on Higher Education Insitutions | K3: Equipment Use | L3: N/A | M3: Laboratory Service | N3: TF-2021-04-02791 | O3: 493079 | P3: 44305
A4: 2021 | B4: 44341 | C4: CS-2021-05-003 | D4: Dominique P. Mediodia | E4: 24210.2 | F4: PAID | G4: =IFERROR(VLOOKUP(D4,'Client ID Records_v2'!D:E, 2, FALSE), "") -> CL-2020-019 | H4: =IFERROR(VLOOKUP(G4,'Client ID Records_v2'!E:F, 2, FALSE), "") -> Institute of Marine Fisheries and Oceanology, College of Fisheries and Ocean Sciences, University of the Philippines Visayas | I4: =IFERROR(VLOOKUP(D4,'Project Records_v2'!E:F, 2, FALSE), "") -> P-2020-008 | J4: =IFERROR(VLOOKUP(I4,'Project Records_v2'!F:G, 2, FALSE), "") -> Marine Fisheries Assessment of Panay: Building Local Fisheries Information through Research Capability Enhancement on Higher Education Insitutions | K4: Equipment Use | L4: N/A | M4: Laboratory Service | N4: TF-2021-06-04996 | O4: 495221 | P4: 44368
A5: 2021 | B5: 44384 | C5: CS-2021-07-004 | D5: Dominique P. Mediodia | E5: 24210.2 | F5: PAID | G5: =IFERROR(VLOOKUP(D5,'Client ID Records_v2'!D:E, 2, FALSE), "") -> CL-2020-019 | H5: =IFERROR(VLOOKUP(G5,'Client ID Records_v2'!E:F, 2, FALSE), "") -> Institute of Marine Fisheries and Oceanology, College of Fisheries and Ocean Sciences, University of the Philippines Visayas | I5: =IFERROR(VLOOKUP(D5,'Project Records_v2'!E:F, 2, FALSE), "") -> P-2020-008 | J5: =IFERROR(VLOOKUP(I5,'Project Records_v2'!F:G, 2, FALSE), "") -> Marine Fisheries Assessment of Panay: Building Local Fisheries Information through Research Capability Enhancement on Higher Education Insitutions | K5: Equipment Use | L5: N/A | M5: Laboratory Service | N5: TF-2021-07-06176 | O5: 497555 | P5: 44405
A6: 2021 | B6: 44392 | C6: CS-2021-07-005 | D6: Arlene L . Avillanosa | E6: 600000.85 | F6: PAID | G6: =IFERROR(VLOOKUP(D6,'Client ID Records_v2'!D:E, 2, FALSE), "") -> CL-2021-031 | H6: =IFERROR(VLOOKUP(G6,'Client ID Records_v2'!E:F, 2, FALSE), "") -> Room 9, Second Floor (ABBA R&D Center), College of Fisheries and Aquatic Science (CFAS), WPU-Puerto Princesa Campus, Sta. Monica, Puerto Princesa City | I6: =IFERROR(VLOOKUP(D6,'Project Records_v2'!E:F, 2, FALSE), "") -> P-2021-013 | J6: =IFERROR(VLOOKUP(I6,'Project Records_v2'!F:G, 2, FALSE), "") -> Genetic Characterization of Macrobrachium populations in the Philippines for broodstock development and seed production | K6: Laboratory Service | L6: Extraction to Amplicon Sequencing | M6: R&D | N6: Thru Bank Deposit | O6: 498868 | P6: 44459
A7: 2021 | B7: 44403 | C7: CS-2021-07-006 | D7: Concepcion Ponce | F7: CANCELLED | G7: =IFERROR(VLOOKUP(D7,'Client ID Records_v2'!D:E, 2, FALSE), "") -> CL-2021-035 | H7: =IFERROR(VLOOKUP(G7,'Client ID Records_v2'!E:F, 2, FALSE), "") -> College of Arts and Sciences (CAS) Buidling, University of the Philippines Visayas, Miagao, Iloilo 5023 | I7: =IFERROR(VLOOKUP(D7,'Project Records_v2'!E:F, 2, FALSE), "") -> P-2021-014 | J7: =IFERROR(VLOOKUP(I7,'Project Records_v2'!F:G, 2, FALSE), "") -> Pre-commercialization of Microwave Extracted Pectin from Waste Calamansi Peels | K7: Retail Sales | L7: Type II Water | M7: Cancelled | N7: N/A | Q7: combined with CS-2021-10-11
A8: 2021 | B8: 44413 | C8: CS-2021-08-007 | D8: Concepcion Ponce | F8: CANCELLED | G8: =IFERROR(VLOOKUP(D8,'Client ID Records_v2'!D:E, 2, FALSE), "") -> CL-2021-035 | H8: =IFERROR(VLOOKUP(G8,'Client ID Records_v2'!E:F, 2, FALSE), "") -> College of Arts and Sciences (CAS) Buidling, University of the Philippines Visayas, Miagao, Iloilo 5023 | I8: =IFERROR(VLOOKUP(D8,'Project Records_v2'!E:F, 2, FALSE), "") -> P-2021-014 | J8: =IFERROR(VLOOKUP(I8,'Project Records_v2'!F:G, 2, FALSE), "") -> Pre-commercialization of Microwave Extracted Pectin from Waste Calamansi Peels | K8: Retail Sales | L8: Type II Water | M8: Cancelled | N8: N/A | Q8: combined with CS-2021-10-12
A9: 2021 | B9: 44420 | C9: CS-2021-08-008 | D9: Concepcion Ponce | F9: CANCELLED | G9: =IFERROR(VLOOKUP(D9,'Client ID Records_v2'!D:E, 2, FALSE), "") -> CL-2021-035 | H9: =IFERROR(VLOOKUP(G9,'Client ID Records_v2'!E:F, 2, FALSE), "") -> College of Arts and Sciences (CAS) Buidling, University of the Philippines Visayas, Miagao, Iloilo 5023 | I9: =IFERROR(VLOOKUP(D9,'Project Records_v2'!E:F, 2, FALSE), "") -> P-2021-014 | J9: =IFERROR(VLOOKUP(I9,'Project Records_v2'!F:G, 2, FALSE), "") -> Pre-commercialization of Microwave Extracted Pectin from Waste Calamansi Peels | K9: Retail Sales | L9: Type II Water | M9: Cancelled | N9: N/A | Q9: combined with CS-2021-10-13
A10: 2021 | B10: 44424 | C10: CS-2021-08-009 | D10: Concepcion Ponce | F10: CANCELLED | G10: =IFERROR(VLOOKUP(D10,'Client ID Records_v2'!D:E, 2, FALSE), "") -> CL-2021-035 | H10: =IFERROR(VLOOKUP(G10,'Client ID Records_v2'!E:F, 2, FALSE), "") -> College of Arts and Sciences (CAS) Buidling, University of the Philippines Visayas, Miagao, Iloilo 5023 | I10: =IFERROR(VLOOKUP(D10,'Project Records_v2'!E:F, 2, FALSE), "") -> P-2021-014 | J10: =IFERROR(VLOOKUP(I10,'Project Records_v2'!F:G, 2, FALSE), "") -> Pre-commercialization of Microwave Extracted Pectin from Waste Calamansi Peels | K10: Retail Sales | L10: Type II Water | M10: Cancelled | N10: N/A | Q10: combined with CS-2021-10-14
A11: 2021 | B11: 44441 | C11: CS-2021-09-010 | D11: Dominique P. Mediodia | E11: 24210.2 | F11: CANCELLED | G11: =IFERROR(VLOOKUP(D11,'Client ID Records_v2'!D:E, 2, FALSE), "") -> CL-2020-019 | H11: =IFERROR(VLOOKUP(G11,'Client ID Records_v2'!E:F, 2, FALSE), "") -> Institute of Marine Fisheries and Oceanology, College of Fisheries and Ocean Sciences, University of the Philippines Visayas | I11: =IFERROR(VLOOKUP(D11,'Project Records_v2'!E:F, 2, FALSE), "") -> P-2020-008 | J11: =IFERROR(VLOOKUP(I11,'Project Records_v2'!F:G, 2, FALSE), "") -> Marine Fisheries Assessment of Panay: Building Local Fisheries Information through Research Capability Enhancement on Higher Education Insitutions | K11: Equipment Use | L11: N/A | M11: Laboratory Service | N11: N/A
A12: 2021 | B12: 44484 | C12: CS-2021-10-011 | D12: Dominique P. Mediodia | E12: 8800 | F12: PAID | G12: =IFERROR(VLOOKUP(D12,'Client ID Records_v2'!D:E, 2, FALSE), "") -> CL-2020-019 | H12: =IFERROR(VLOOKUP(G12,'Client ID Records_v2'!E:F, 2, FALSE), "") -> Institute of Marine Fisheries and Oceanology, College of Fisheries and Ocean Sciences, University of the Philippines Visayas | I12: =IFERROR(VLOOKUP(D12,'Project Records_v2'!E:F, 2, FALSE), "") -> P-2020-008 | J12: =IFERROR(VLOOKUP(I12,'Project Records_v2'!F:G, 2, FALSE), "") -> Marine Fisheries Assessment of Panay: Building Local Fisheries Information through Research Capability Enhancement on Higher Education Insitutions | K12: Equipment Use | L12: N/A | M12: Laboratory Service | N12: TF-2021-12-10531 | O12: 508210 | P12: 44553
A13: 2022 | B13: 44673 | C13: CS-2022-01-001 | D13: Kingsley John de los Santos | E13: 1320 | F13: PAID | G13: =IFERROR(VLOOKUP(D13,'Client ID Records_v2'!D:E, 2, FALSE), "") -> CL-2022-044 | H13: =IFERROR(VLOOKUP(G13,'Client ID Records_v2'!E:F, 2, FALSE), "") -> Division of Biological Sciences, College of Arts and Sciences, University of the Philippines Visayas, Miagao, Iloilo | I13: =IFERROR(VLOOKUP(D13,'Project Records_v2'!E:F, 2, FALSE), "") -> P-2022-022 | J13: =IFERROR(VLOOKUP(I13,'Project Records_v2'!F:G, 2, FALSE), "") -> Assessment of Anthropogenic Marine Debris and Mangrove Forest Health in Iloilo Strait, Western Visayas, Philippines | K13: Retail Sales | L13: Liquid Nitrogen (LN) | M13: Laboratory Service | N13: Bank Deposit | O13: 512050 | P13: 44673
A14: 2022 | B14: 44673 | C14: CS-2022-01-002 | D14: Karl Angelo P. Tenizo | E14: 1205945 | F14: PAID | G14: =IFERROR(VLOOKUP(D14,'Client ID Records_v2'!D:E, 2, FALSE), "") -> CL-2020-015 | H14: =IFERROR(VLOOKUP(G14,'Client ID Records_v2'!E:F, 2, FALSE), "") -> Institute of Aquaculture, College of Fisheries and Ocean Sciences, University of the Philippines Visayas, Miagao, 5023, Iloilo | I14: =IFERROR(VLOOKUP(D14,'Project Records_v2'!E:F, 2, FALSE), "") -> P-2020-005 | J14: =IFERROR(VLOOKUP(I14,'Project Records_v2'!F:G, 2, FALSE), "") -> Transcriptome and metabolome profiling of seaweeds to elucidate "ice-ice" disease and epiphyte infestation mechanisms | K14: Laboratory Service | L14: Extraction to Transcriptomics | M14: R&D | N14: TF-2022-05-3955
A15: 2022 | B15: 44697 | C15: CS-2022-05-003 | D15: Rema C. Sibonga | E15: 3033.36 | F15: PAID | G15: =IFERROR(VLOOKUP(D15,'Client ID Records_v2'!D:E, 2, FALSE), "") -> CL-2020-010 | H15: =IFERROR(VLOOKUP(G15,'Client ID Records_v2'!E:F, 2, FALSE), "") -> Institute of Aquaculture, College of Fisheries and Ocean Sciences, University of the Philippines Visayas, Miagao, 5023, Iloilo | I15: =IFERROR(VLOOKUP(D15,'Project Records_v2'!E:F, 2, FALSE), "") -> P-2020-001 | J15: =IFERROR(VLOOKUP(I15,'Project Records_v2'!F:G, 2, FALSE), "") -> Global Seaweed STAR Project | K15: Equipment Use | L15: N/A | M15: Laboratory Service | N15: Bank Deposit | O15: 514345 | P15: 44722
A16: 2022 | B16: 44701 | C16: CS-2022-05-004 | D16: Kingsley John de los Santos | E16: 1320 | F16: PAID | G16: =IFERROR(VLOOKUP(D16,'Client ID Records_v2'!D:E, 2, FALSE), "") -> CL-2022-044 | H16: =IFERROR(VLOOKUP(G16,'Client ID Records_v2'!E:F, 2, FALSE), "") -> Division of Biological Sciences, College of Arts and Sciences, University of the Philippines Visayas, Miagao, Iloilo | I16: =IFERROR(VLOOKUP(D16,'Project Records_v2'!E:F, 2, FALSE), "") -> P-2022-022 | J16: =IFERROR(VLOOKUP(I16,'Project Records_v2'!F:G, 2, FALSE), "") -> Assessment of Anthropogenic Marine Debris and Mangrove Forest Health in Iloilo Strait, Western Visayas, Philippines | K16: Retail Sales | L16: Liquid Nitrogen (LN) | M16: Laboratory Service | N16: Bank Deposit | O16: 512685 | P16: 44701
A17: 2022 | B17: 44733 | C17: CS-2022-06-005 | D17: Arlene L . Avillanosa | E17: 193203.97 | F17: PAID | G17: =IFERROR(VLOOKUP(D17,'Client ID Records_v2'!D:E, 2, FALSE), "") -> CL-2021-031 | H17: =IFERROR(VLOOKUP(G17,'Client ID Records_v2'!E:F, 2, FALSE), "") -> Room 9, Second Floor (ABBA R&D Center), College of Fisheries and Aquatic Science (CFAS), WPU-Puerto Princesa Campus, Sta. Monica, Puerto Princesa City | I17: =IFERROR(VLOOKUP(D17,'Project Records_v2'!E:F, 2, FALSE), "") -> P-2021-013 | J17: =IFERROR(VLOOKUP(I17,'Project Records_v2'!F:G, 2, FALSE), "") -> Genetic Characterization of Macrobrachium populations in the Philippines for broodstock development and seed production | K17: Laboratory Service | L17: Extraction to Amplicon Sequencing | M17: R&D | N17: Bank Deposit | O17: 0517969 | P17: 44792
A18: 2022 | B18: 44551 | C18: CS-2021-12-012 / CS-2022-07-006 | D18: Angel Queenee D. Dequito | E18: 76402.48 | G18: =IFERROR(VLOOKUP(D18,'Client ID Records_v2'!D:E, 2, FALSE), "") -> CL-2020-013 | H18: =IFERROR(VLOOKUP(G18,'Client ID Records_v2'!E:F, 2, FALSE), "") -> Institute of Aquaculture, College of Fisheries and Ocean Sciences, University of the Philippines Visayas, Miagao, 5023, Iloilo | I18: =IFERROR(VLOOKUP(D18,'Project Records_v2'!E:F, 2, FALSE), "") -> P-2020-003 | J18: =IFERROR(VLOOKUP(I18,'Project Records_v2'!F:G, 2, FALSE), "") -> Transcriptome and Gut Metagenome Profile of Penaeus vannamei Exposed to Fluctuating Environmental Temperatures | K18: Laboratory Service | L18: Extraction to qPCR | M18: Cancelled | N18: Bank Deposit
A19: 2022 | B19: 44803 | C19: CS-2022-08-007 | D19: Beverly T. Jaspe | E19: 123497 | F19: PAID | G19: =IFERROR(VLOOKUP(D19,'Client ID Records_v2'!D:E, 2, FALSE), "") -> CL-2022-051 | H19: =IFERROR(VLOOKUP(G19,'Client ID Records_v2'!E:F, 2, FALSE), "") -> Fisheries and Marine Sciences Department, Aklan State University - New Washington Campus | I19: =IFERROR(VLOOKUP(D19,'Project Records_v2'!E:F, 2, FALSE), "") -> P-2022-027 | J19: =IFERROR(VLOOKUP(I19,'Project Records_v2'!F:G, 2, FALSE), "") -> Genomic variations among different (meta) populations of oriental angelwing clam (Pholas orientalis) in the Western Visayas, Philippines: basis for conservation breeding program | K19: Laboratory Service | L19: Extraction to Bioinformatics Analysis | M19: R&D | N19: Thru Bank Deposit | O19: 0520397 | P19: 44816
A20: 2022 | B20: 44816 | C20: CS-2022-09-009 | D20: Viva Princess A. Basa | E20: 58367.86 | F20: PAID | G20: =IFERROR(VLOOKUP(D20,'Client ID Records_v2'!D:E, 2, FALSE), "") -> CL-2022-056 | H20: =IFERROR(VLOOKUP(G20,'Client ID Records_v2'!E:F, 2, FALSE), "") -> Research and Development Extension, Mindoro State University | I20: PGCV-BT-2022-001 | J20: =IFERROR(VLOOKUP(I20,'Project Records_v2'!F:G, 2, FALSE), "") | K20: Training | L20: Bioinformatics Analysis | M20: Laboratory Service | N20: Bank Deposit | O20: 0520474 | P20: 44817 | Q20: Other Payee: MS. KATHERINE P. SANCHEZ MS. JERMAINE RITZCHELLE D. MARQUEZ MS. ELSIE Y. GUIBONE
A21: 2022 | B21: 44881 | C21: CS-2022-11-010 | D21: Eric Zeus C. Rizo | E21: 569499.72 | F21: PAID | G21: =IFERROR(VLOOKUP(D21,'Client ID Records_v2'!D:E, 2, FALSE), "") -> CL-2022-038 | H21: =IFERROR(VLOOKUP(G21,'Client ID Records_v2'!E:F, 2, FALSE), "") -> Division of Biological Sciences, College of Arts and Sciences, University of the Philippines Visayas, Miagao, Iloilo | I21: =IFERROR(VLOOKUP(D21,'Project Records_v2'!E:F, 2, FALSE), "") -> P-2022-017 | J21: =IFERROR(VLOOKUP(I21,'Project Records_v2'!F:G, 2, FALSE), "") -> Development of a Water Quality Biological Monitoring Protocol using Genetic, Phylogenetic and Functional Diversity on Freshwater Zooplankton Communitites in Inland Waters of Panay Island, Philippines | K21: Laboratory Service | L21: Extraction to Sequencing | M21: R&D | N21: 2022-11-11214 | O21: Check No: 63422 | P21: 44917
A22: 2022 | B22: 44901 | C22: CS-2022-12-011 | D22: Rhudith Cabulong | E22: 126740.68 | F22: CANCELLED | G22: =IFERROR(VLOOKUP(D22,'Client ID Records_v2'!D:E, 2, FALSE), "") -> CL-2022-055 | H22: =IFERROR(VLOOKUP(G22,'Client ID Records_v2'!E:F, 2, FALSE), "") -> Microbiology Laboratory, College of Arts and Sciences, University of the Philippines Visayas, 5023 Miagao, Iloilo | I22: =IFERROR(VLOOKUP(D22,'Project Records_v2'!E:F, 2, FALSE), "") -> P-2022-032 | J22: =IFERROR(VLOOKUP(I22,'Project Records_v2'!F:G, 2, FALSE), "") -> Diversity and screening of culturable cellulytic microorganisms from mangrove forests, natural parks, paddy field, and sugar plantation in Panay Island, Philippines | K22: Laboratory Service | L22: Extraction to Sequencing | M22: Cancelled | N22: N/A | O22: N/A | P22: N/A | Q22: PLEASE DISREGARD, updated and final charge slip is CS-2022-12-012
A23: 2022 | B23: 44904 | C23: CS-2022-12-012 | D23: Rhudith Cabulong | E23: 140870.31 | F23: PAID | G23: =IFERROR(VLOOKUP(D23,'Client ID Records_v2'!D:E, 2, FALSE), "") -> CL-2022-055 | H23: =IFERROR(VLOOKUP(G23,'Client ID Records_v2'!E:F, 2, FALSE), "") -> Microbiology Laboratory, College of Arts and Sciences, University of the Philippines Visayas, 5023 Miagao, Iloilo | I23: =IFERROR(VLOOKUP(D23,'Project Records_v2'!E:F, 2, FALSE), "") -> P-2022-032 | J23: =IFERROR(VLOOKUP(I23,'Project Records_v2'!F:G, 2, FALSE), "") -> Diversity and screening of culturable cellulytic microorganisms from mangrove forests, natural parks, paddy field, and sugar plantation in Panay Island, Philippines | K23: Laboratory Service | L23: Extraction to Sequencing | M23: R&D | N23: 2022-12-12406 | O23: Check No. 122888 | P23: 44915
A24: 2022 | B24: 44909 | C24: CS-2023-12-013 | D24: Eric Zeus C. Rizo | E24: 43309.98 | F24: PAID | G24: =IFERROR(VLOOKUP(D24,'Client ID Records_v2'!D:E, 2, FALSE), "") -> CL-2022-038 | H24: =IFERROR(VLOOKUP(G24,'Client ID Records_v2'!E:F, 2, FALSE), "") -> Division of Biological Sciences, College of Arts and Sciences, University of the Philippines Visayas, Miagao, Iloilo | I24: =IFERROR(VLOOKUP(D24,'Project Records_v2'!E:F, 2, FALSE), "") -> P-2022-017 | J24: =IFERROR(VLOOKUP(I24,'Project Records_v2'!F:G, 2, FALSE), "") -> Development of a Water Quality Biological Monitoring Protocol using Genetic, Phylogenetic and Functional Diversity on Freshwater Zooplankton Communitites in Inland Waters of Panay Island, Philippines | K24: Laboratory Service | L24: Extraction to Sequencing | M24: R&D | N24: 2022-12-12069 | O24: Check No: 63513 | P24: 44923
A25: 2022 | B25: 44915 | C25: CS-2023-12-014 | D25: Alain C. Juayang | F25: CANCELLED | G25: =IFERROR(VLOOKUP(D25,'Client ID Records_v2'!D:E, 2, FALSE), "") -> CL-2021-025 | H25: =IFERROR(VLOOKUP(G25,'Client ID Records_v2'!E:F, 2, FALSE), "") -> Molecular Laboratory, Corazon L. Montelibano Memorial Regional Hospital, Burgos-Lacson St., Bacolod City | I25: T-2023-001 | J25: =IFERROR(VLOOKUP(I25,'Project Records_v2'!F:G, 2, FALSE), "") | K25: Training | L25: WGS | M25: Cancelled | Q25: PLEASE DISREGARD, updated and final charge slip is CS-2023-01-002
A26: 2023 | B26: 44946 | C26: CS-2023-01-001 | D26: Karl Angelo P. Tenizo | E26: 420582.18 | F26: CANCELLED | G26: =IFERROR(VLOOKUP(D26,'Client ID Records_v2'!D:E, 2, FALSE), "") -> CL-2020-015 | H26: =IFERROR(VLOOKUP(G26,'Client ID Records_v2'!E:F, 2, FALSE), "") -> Institute of Aquaculture, College of Fisheries and Ocean Sciences, University of the Philippines Visayas, Miagao, 5023, Iloilo | I26: =IFERROR(VLOOKUP(D26,'Project Records_v2'!E:F, 2, FALSE), "") -> P-2020-005 | J26: =IFERROR(VLOOKUP(I26,'Project Records_v2'!F:G, 2, FALSE), "") -> Transcriptome and metabolome profiling of seaweeds to elucidate "ice-ice" disease and epiphyte infestation mechanisms | K26: Laboratory Service | L26: Extraction to Transcriptomics | M26: Cancelled
